2023-06-09 00:15:08,445 INFO    StreamThr :89786 [internal.py:wandb_internal():86] W&B internal server running at pid: 89786, started at: 2023-06-09 00:15:08.445031
2023-06-09 00:15:08,446 DEBUG   HandlerThread:89786 [handler.py:handle_request():144] handle_request: status
2023-06-09 00:15:08,449 INFO    WriterThread:89786 [datastore.py:open_for_write():85] open: /Users/toph/Documents/Private/GitHub/MLOps-Zoomcamp/wandb/run-20230609_001508-3zfxrby4/run-3zfxrby4.wandb
2023-06-09 00:15:08,450 DEBUG   SenderThread:89786 [sender.py:send():369] send: header
2023-06-09 00:15:08,477 DEBUG   SenderThread:89786 [sender.py:send():369] send: run
2023-06-09 00:15:08,826 ERROR   SenderThread:89786 [internal_api.py:execute():323] 404 response executing GraphQL.
2023-06-09 00:15:08,827 ERROR   SenderThread:89786 [internal_api.py:execute():324] {"errors":[{"message":"entity ch w not found during upsertBucket","path":["upsertBucket"]}],"data":{"upsertBucket":null}}
2023-06-09 00:15:08,827 ERROR   SenderThread:89786 [sender.py:send_run():955] It appears that you do not have permission to access the requested resource. Please reach out to the project owner to grant you access. If you have the correct permissions, verify that there are no issues with your networking setup.(Error 404: Not Found)
Traceback (most recent call last):
  File "/opt/homebrew/anaconda3/envs/mlops_zoomcamp/lib/python3.11/site-packages/wandb/sdk/lib/retry.py", line 131, in __call__
    result = self._call_fn(*args, **kwargs)
             ^^^^^^^^^^^^^^^^^^^^^^^^^^^^^^
  File "/opt/homebrew/anaconda3/envs/mlops_zoomcamp/lib/python3.11/site-packages/wandb/sdk/internal/internal_api.py", line 320, in execute
    return self.client.execute(*args, **kwargs)  # type: ignore
           ^^^^^^^^^^^^^^^^^^^^^^^^^^^^^^^^^^^^
  File "/opt/homebrew/anaconda3/envs/mlops_zoomcamp/lib/python3.11/site-packages/wandb/vendor/gql-0.2.0/wandb_gql/client.py", line 52, in execute
    result = self._get_result(document, *args, **kwargs)
             ^^^^^^^^^^^^^^^^^^^^^^^^^^^^^^^^^^^^^^^^^^^
  File "/opt/homebrew/anaconda3/envs/mlops_zoomcamp/lib/python3.11/site-packages/wandb/vendor/gql-0.2.0/wandb_gql/client.py", line 60, in _get_result
    return self.transport.execute(document, *args, **kwargs)
           ^^^^^^^^^^^^^^^^^^^^^^^^^^^^^^^^^^^^^^^^^^^^^^^^^
  File "/opt/homebrew/anaconda3/envs/mlops_zoomcamp/lib/python3.11/site-packages/wandb/sdk/lib/gql_request.py", line 56, in execute
    request.raise_for_status()
  File "/opt/homebrew/anaconda3/envs/mlops_zoomcamp/lib/python3.11/site-packages/requests/models.py", line 1021, in raise_for_status
    raise HTTPError(http_error_msg, response=self)
requests.exceptions.HTTPError: 404 Client Error: Not Found for url: https://api.wandb.ai/graphql

During handling of the above exception, another exception occurred:

Traceback (most recent call last):
  File "/opt/homebrew/anaconda3/envs/mlops_zoomcamp/lib/python3.11/site-packages/wandb/sdk/internal/sender.py", line 953, in send_run
    self._init_run(run, config_value_dict)
  File "/opt/homebrew/anaconda3/envs/mlops_zoomcamp/lib/python3.11/site-packages/wandb/sdk/internal/sender.py", line 991, in _init_run
    server_run, inserted, server_messages = self._api.upsert_run(
                                            ^^^^^^^^^^^^^^^^^^^^^
  File "/opt/homebrew/anaconda3/envs/mlops_zoomcamp/lib/python3.11/site-packages/wandb/apis/normalize.py", line 73, in wrapper
    raise err
  File "/opt/homebrew/anaconda3/envs/mlops_zoomcamp/lib/python3.11/site-packages/wandb/apis/normalize.py", line 41, in wrapper
    return func(*args, **kwargs)
           ^^^^^^^^^^^^^^^^^^^^^
  File "/opt/homebrew/anaconda3/envs/mlops_zoomcamp/lib/python3.11/site-packages/wandb/sdk/internal/internal_api.py", line 1727, in upsert_run
    response = self.gql(
               ^^^^^^^^^
  File "/opt/homebrew/anaconda3/envs/mlops_zoomcamp/lib/python3.11/site-packages/wandb/sdk/internal/internal_api.py", line 292, in gql
    ret = self._retry_gql(
          ^^^^^^^^^^^^^^^^
  File "/opt/homebrew/anaconda3/envs/mlops_zoomcamp/lib/python3.11/site-packages/wandb/sdk/lib/retry.py", line 147, in __call__
    retry_timedelta_triggered = check_retry_fn(e)
                                ^^^^^^^^^^^^^^^^^
  File "/opt/homebrew/anaconda3/envs/mlops_zoomcamp/lib/python3.11/site-packages/wandb/util.py", line 908, in check_retry_fn
    return fallback_retry_fn(e)
           ^^^^^^^^^^^^^^^^^^^^
  File "/opt/homebrew/anaconda3/envs/mlops_zoomcamp/lib/python3.11/site-packages/wandb/util.py", line 850, in no_retry_auth
    raise CommError(
wandb.errors.CommError: It appears that you do not have permission to access the requested resource. Please reach out to the project owner to grant you access. If you have the correct permissions, verify that there are no issues with your networking setup.(Error 404: Not Found)
2023-06-09 00:15:09,000 DEBUG   HandlerThread:89786 [handler.py:handle_request():144] handle_request: shutdown
2023-06-09 00:15:09,000 INFO    HandlerThread:89786 [handler.py:finish():854] shutting down handler
2023-06-09 00:15:09,482 INFO    WriterThread:89786 [datastore.py:close():298] close: /Users/toph/Documents/Private/GitHub/MLOps-Zoomcamp/wandb/run-20230609_001508-3zfxrby4/run-3zfxrby4.wandb
2023-06-09 00:15:09,844 INFO    SenderThread:89786 [sender.py:finish():1526] shutting down sender
